Workbook

Sheet Instructions_Disclaimer
M7: © 2014
B8: LM5066I Design Tool- Rev. C
B10: Typical design procedure
B11: Typical applications require multiple passes through the design tool using MOSFET factors such as transient
B12: thermal response and safe operating area curves. Refer to the following application reports for more detail.
B14: Robust Hot Swap Design
B15: LM5066I Datasheet (See "Applications and Implementation")
B17: The basic design process follows:
B18: 1. Enter operating conditions.
B19: 2. Select current limit parameters.
B20: 3. Enter MOSTFET SOA characteristics & power limit.
B21: 4. Select start up conditions (load and/or soft start). Check whether FET is operating with reasonable margin, within the SOA curve.
B22: If not, try changing start-up conditions (soft start values, timer values), add more FETs in parallel, or switch to FET with better SOA.
... B36: TEXAS INSTRUMENTS TEXT FILE LICENSE Copyright (c) 2014 Texas Instruments Incorporated All rights reserved not granted herein. Limited License. Texas Instruments Incorporated grants a world-wide, royalty-free, non-exclusive license under copyrights and patents it now or hereafter owns or controls to make, have made, use, import, offer to sell and sell ("Utilize") this software subject to the terms herein. With respect to the foregoing patent license, such license is granted solely to the extent that any such patent is necessary to Utilize the software alone. The patent license shall not apply to any combinations which include this software, other than combinations with devices manufactured by or for TI (“TI Devices”). No hardware patent is licensed hereunder. Redistributions must preserve existing copyright notices and reproduce this license (including the above copyright notice and the disclaimer and (if applicable) source code license limitations below) in the documentation and/or other materials provided with the distribution Redistribution and use in binary form, without modification, are permitted provided that the following conditions are met: * No reverse engineering, decompilation, or disassembly of this software is permitted with respect to any software provided in binary form. * any redistribution and use are licensed by TI for use only with TI Devices. * Nothing shall obligate TI to provide you with source code for the software licensed and provided to you in object code. If software source code is provided to you, modification and redistribution of the source code are permitted provided that the following conditions are met: * any redistribution and use of the source code, including any resulting derivative works, are licensed by TI for use only with TI Devices. * any redistribution and use of any object code compiled from the source code and any resulting derivative works, are licensed by TI for use only with TI Devices. Neither the name of Texas Instruments Incorporated nor the names of its suppliers may be used to endorse or promote products derived from this software without specific prior written permission. DISCLAIMER. THIS SOFTWARE IS PROVIDED BY TI AND TI’S LICENSORS "AS IS" AND ANY EXPRESS OR IMPLIED WARRANTIES, INCLUDING, BUT NOT LIMITED TO, THE IMPLIED WARRANTIES OF MERCHANTABILITY AND FITNESS FOR A PARTICULAR PURPOSE ARE DISCLAIMED. IN NO EVENT SHALL TI AND TI’S LICENSORS BE LIABLE FOR ANY DIRECT, INDIRECT, INCIDENTAL, SPECIAL, EXEMPLARY, OR CONSEQUENTIAL DAMAGES (INCLUDING, BUT NOT LIMITED TO, PROCUREMENT OF SUBSTITUTE GOODS OR SERVICES; LOSS OF USE, DATA, OR PROFITS; OR BUSINESS INTERRUPTION) HOWEVER CAUSED AND ON ANY THEORY OF LIABILITY, WHETHER IN CONTRACT, STRICT LIABILITY, OR TORT (INCLUDING NEGLIGENCE OR OTHERWISE) ARISING IN ANY WAY OUT OF THE USE OF THIS SOFTWARE, EVEN IF ADVISED OF THE POSSIBILITY OF SUCH DAMAGE.

Sheet Design Calculator
A1: LM5066I PMBus Hot Swap Design Tool
B2: www.ti.com/hotswap
D9: Enter Values in Green Shaded Cells
D10: Calculated Values are shown in White Cells
D11: Yellow and Red cells highlight potential issues with the design. Red highlights items that are higher risk.
B14: Step 0: Calculator Tutorials | D14: Note: Before proceeding, please watch the video tutorials listed to ensure accurate results from this tool! | AU14: Yes
AU15: No
D16: Steps 1 & 2: Operating Conditions, Current Limit, & Circuit Breaker (7:41)
D17: Step 3: MOSFET Selection (9:58)
D18: Step 4: Startup (10:32)
D19: Step 5: UVLO, OVLO & PGD Thresholds (4:20)
D20: LM5066I Datasheet
D22: I understand and agree to watch the video tutorials if help is needed. (Choose Yes to enable the calculator.) | G22: Yes
D23: Assure to follow the layout and application guidelines listed on the datasheet. | G23: Yes
D24: *For additional questions not addressed in the videos, please post on E2E.ti.com
B27: Step 1: Operating Conditions | E27: Minimum Input Operating Voltage: VIN(MIN) | F27: 10 | G27: V
E28: Nominal Input Operating Voltage: VIN(NOM) | F28: 48 | G28: V
E29: Maximum Input Operating Voltage: VIN(MAX) | F29: 50 | G29: V
E30: Maximum Load Current: IOUT(MAX) | F30: 78 | G30: A
E31: Maximum Output Load Capacitance: CLOAD | F31: 4000 | G31: µF
E32: Maximum Ambient Operating Temperature: TMAX | F32: 85 | G32: oC
B33: Steps 1 & 2: Operating Conditions, Current Limit, & Circuit Breaker
B38: Step 2: Current Limit and Circuit Breaker | E38: Current Limit Range (CL) | F38: 26 mV | AN38: 26 mV
E39: Maximum Recommended Value for Effective Sense Resistance | F39: =Equations!F9 -> 0.2970297 | G39: mW | AN39: 50 mV
E40: Use External Resistor Divider to Reduce Effecitve RS | F40: No | AN40: Yes
E41: Enter the Resistance for RS | F41: 0.3 | G41: mW | AN41: No
E42: Recommended Value for RCL1 | F42: =Equations!F10 -> 10 | G42: W
E43: Recommended Value for RCL2 | F43: =Equations!F11 -> 0 | G43: W
E44: Enter value for RCL1 | F44: 10 | G44: W | AN44: =AND(F40="No") -> 1
B45: Steps 1 & 2: Operating Conditions, Current Limit, & Circuit Breaker | E45: Enter value for RCL2 | F45: 3.04 | G45: W
E46: Effective Sense Resistance (RS,EFF) | F46: =RsEFF -> 0.3 | G46: mW
E47: Resulting Minimum Current Limit | F47: =CLMIN -> 78 | G47: A
E48: Resulting Typical Current Limit | F48: =CLNOM -> 86.666667 | G48: A
E49: Resulting Maximum Current Limit | F49: =CLMAX -> 95.333333 | G49: A | AN49: Retry
E50: Maximum Power Dissipation in RS | F50: =Equations!F16/1000 -> 2.7265333 | G50: W | AN50: Latch Off
E51: Fault Response | F51: Retry | AN51: 1.9 x Current Limit
E52: Circuit Breaker to Current Limit Raitio | F52: 1.9 x Current Limit | AN52: 3.9 x Current Limit
B53: Step 3: MOSFET Selection | E53: Q1 FET Name | F53: PSMN4R8-100BSE | AP53: # FETS | AQ53: 3
E54: Estimated MOSFET RQJA | F54: =40/AQ53 -> 13.333333 | G54: oC/W | AN54: =((((TJMAX-TAMB)/ThetaJA)/(CLMAX^2))*1000)*NUMFETS^2 -> 3.0120666 | AO54: =((TJMAX-TAMB)/ThetaJA) -> 27.375
E55: Number of MosFETs | F55: 1 | G55: # | AN55: Values Used
...

Sheet Device Parameters
C2: Min | D2: Typ | E2: Max | F2: Units
A3: Operating Conditions
B4: Junction Temperature | C4: -40 | E4: 125
B5: Input Voltage | C5: 10 | E5: 80 | F5: V
A6: Current Limit
B7: Threshold Voltage CL = VDD | C7: 23.4 | D7: 26 | E7: 28.6
B8: Threshold Voltage CL = GND | C8: 45 | D8: 50 | E8: 55
B9: Sense input Current | C9: 20 | D9: 25 | E9: 35 | F9: uA
A11: Power Limit
B12: Systematic Offset | E12: 0.001 | F12: V
B13: Minimum Recommended Vsns | E13: 0.004 | F13: V | G13: <= I am assuming this would have +/- 50% error at best
B14: A_coeff | E14: =1/(0.000007) -> 142857.14
B16: Key Equations: | C16: Vsns = Rpwr / (A*Vds) + Vos,syst | I16: Example: | J16: Vds | K16: Rpwr | L16: Rsns (m-ohm) | M16: Plim | N16: Vsns (mV) | P16: Plim | Q16: Rpwr
C17: Plim (Vds) = 1/Rs * [ Rpwr/A + Vds * Vos, syst= | J17: 12 | K17: 25 | L17: =0.5 -> 0.5 | M17: =1/(0.001*L17)*(K17*1000/$E$14+J17*$E$12) -> 374 | N17: =K17*1000/$E$14/J17+$E$12 -> 0.015583333 | P17: 82 | Q17: =E14*(P17*L17*0.001-J17*E12) -> 4142.8571
C18: Rpwr = A * [PLIM(Vds) * Rs - 0.043] | J18: 12 | K18: 5 | L18: =0.5 -> 0.5 | M18: =1/(0.001*L18)*(K18*1000/$E$14+J18*$E$12) -> 94 | N18: =K18*1000/$E$14/J18+$E$12*0.001 -> 0.0029176667
B19: How Plim varries vs Vds: | I19: Ex: Plim @ 13V = 100W, Rs = 0.5; Plim @ (Vds = 5V) = 100W - 7V * 1mV/0.5mili-ohm = 100W - 14W = 86W
A21: Timer
B22: Upper Threshold | C22: 3.74 | D22: 3.9 | E22: 4.07 | F22: V
B23: Insertion Time Current | C23: -5.9 | D23: -4.8 | E23: -3.3 | F23: uA
B24: timer_constant
B25: Fault detection current | C25: 90 | D25: 75 | E25: 60 | F25: uA
B26: Computed Start - Up Slop | D26: =SQRT(0.66^2+ ((120-90)/90)^2+ 0.1^2) -> 0.74613076 | G26: <= mean root square(T_start_error_Plim, timer_error, cap_error); T_start proportional to 1/Plim => T_start_error_plim = 1/(1-Plim_err) - 1 = 1/(1-0.4) - 1 = 0.66
B27: Slop for calculations | D27: 0.5 | G27: Note: We get additional buffer, b/c this is designed for a Vinmax, while typically Vin = Vinnom
A29: Gate
B30: Gate Sourcing Current | C30: 7.5 | D30: 20 | E30: 40
A32: Circuit Breaker | C32: 26mV | F32: 50mV
B33: 1.9 x Threshold | C33: 38 | D33: 48 | E33: 58 | F33: 76 | G33: 96 | H33: 116
B34: 1.9x CB:CL Ratio | C34: 1.5 | D34: 1.88 | E34: 2.3 | F34: 1.64 | G34: 1.94 | H34: 2.23
B35: 3.9 x Threshold | C35: 76 | D35: 96 | E35: 116 | F35: 155 | G35: 193 | H35: 235
B36: 3.9x CB:CL Ratio | C36: 3.1 | D36: 3.75 | E36: 4.45 | F36: 3.28 | G36: 3.87 | H36: 4.45
A38: Timer Pin
B39: Upper Threshold | C39: 3.74 | D39: 3.9 | E39: 4.07
B40: Lower Threshold (Restart) | C40: 1 | D40: 1.2 | E40: 1.4
B41: End of Cycle | D41: 0.3
B42: Re-enable threshold | D42: 0.3
B43: Insertion time current | C43: 3.3 | D43: 4.8 | E43: 5.9
B44: Sink current, end of insertion | C44: 0.9 | D44: 1.5 | E44: 2.1
B45: Fault detection current | C45: 60 | D45: 75 | E45: 90
B46: Fault sink current | C46: 1.7 | D46: 2.8 | E46: 3.2
A48: Power Good
...

Sheet Equations
A2: Current Limit
D4: CLMIN = | E4: =IF('Design Calculator'!$F$38="26 mV",'Device Parameters'!C7,'Device Parameters'!C8) -> 23.4 | F4: mV
D5: CLNOM = | E5: =IF('Design Calculator'!$F$38="26 mV",'Device Parameters'!D7,'Device Parameters'!D8) -> 26 | F5: mV
D6: CLMAX = | E6: =IF('Design Calculator'!$F$38="26 mV",'Device Parameters'!E7,'Device Parameters'!E8) -> 28.6 | F6: mV
E9: Max Rs = | F9: =CLMIN_Threshold/('Design Calculator'!F30*1.01) -> 0.2970297
E10: RCL1 Recommended = | F10: =IF(Rs>RsMAX,10,"NA") -> 10
E11: RCL2 Recommmended = | F11: =IF(Rs>RsMAX,(((IOUTMAX*Rs)/CLMIN_Threshold)-1)*F10,"NA") -> 0
E12: Effective Rs = | F12: =IF(RsMAX>Rs,Rs,IF('Design Calculator'!F40="Yes",IF(Rs>RsMAX,Rs/(1+RDIV2/RDIV1),Rs),Rs)) -> 0.3
E13: Min. Current limit = | F13: =CLMIN_Threshold/RsEFF -> 78
E14: Typ. Current limit = | F14: =CLNOM_Threshold/RsEFF -> 86.666667
E15: Max. Current limit = | F15: =CLMAX_Threshold/RsEFF -> 95.333333
E16: Rs Power Diss. = | F16: =F15^2*'Design Calculator'!F41 -> 2726.5333
E19: CB threshold: | F19: =CLNOM_Threshold*IF('Design Calculator'!F52 = "1.9 x Current Limit", 1.9, 3.9) -> 49.4 | G19: mV
E20: CB threshold | F20: =F19/RsEFF -> 164.66667 | G20: A
A22: FET Selection
F23: Nominal | H23: Derated at TJ
E24: 100ms SOA Current Maximum Input Voltage | F24: =VINMAX*'Design Calculator'!F58 -> 15000 | G24: W | H24: =F24*(TJMAX-TJ)/(TJMAX-25) -> 3720.5647
E25: 1ms SOA Current Maximum Input Voltage | F25: =VINMAX*'Design Calculator'!F59 -> 4050 | G25: W | H25: =F25*(TJMAX-TJ)/(TJMAX-25) -> 1004.5525
E26: 10ms SOA Current Maximum Input Voltage | F26: =VINMAX*'Design Calculator'!F60 -> 900 | G26: W | H26: =F26*(TJMAX-TJ)/(TJMAX-25) -> 223.23388
E27: 100ms or DC SOA Current at Maximum Input Voltage | F27: =VINMAX*'Design Calculator'!F61 -> 315 | G27: W | H27: =F27*(TJMAX-TJ)/(TJMAX-25) -> 78.131859
E29: Minimum Power Limit= | F29: =VINMAX*'Device Parameters'!E13/RsEFF/0.001 -> 666.66667 | G29: W
E30: Target PLIM | F30: ='Design Calculator'!F66 -> 700 | G30: W
E31: Rpwr | F31: ='Device Parameters'!E14*(F30*RsEFF*0.001-0.043)/1000 -> 23.857143 | G31: k-ohm
E32: Rpwr actual | F32: =RPWR -> 24 | G32: k-ohm
E33: Final Plim | F33: =1/RsEFF*1000*(Equations!F32*1000/'Device Parameters'!E14+0.043) -> 703.33333 | G33: W
E37: Resulting Typical Power Limit = | F37: =F38*(1-0.24) -> 534.53333 | G37: 24% tolerance used in this calculation.
E38: Resulting Minimum Power Limit = | F38: =F33 -> 703.33333
E39: Resulting Maximum Power Limit = | F39: =F38*(1+0.24) -> 872.13333
A42: Startup
D43: With PLIM
E44: Typical Start time | F44: =Start_up!M2 -> 32.5 | G44: ms
E45: Start-slop | F45: ='Device Parameters'!D27 -> 0.5
E46: Target Fault Timer | F46: =F44*(1+F45) -> 48.75 | G46: ms
E47: Target Timer capacitance | F47: ='Device Parameters'!D25/'Device Parameters'!D22*F46 -> 937.5 | G47: nF
E48: Selected Timer capacitance | F48: ='Design Calculator'!F78 -> 20000 | G48: nF
E49: Final Fault Timer | F49: ='Device Parameters'!D22/'Device Parameters'!D25*F48 -> 1040 | G49: ms
E50: SOA / PLIM | F50: =SOA!C26/F38 -> 2.0715824
D51: With SS
E52: dv/dt rate | F52: ='Design Calculator'!F84 -> 1.5 | G52: V/ms
E53: calculated SS capacitance | F53: ='Device Parameters'!D30/ss_rate -> 13.333333 | G53: nF
...

Sheet Start_up
B1: PLIM | C1: ILIM | D1: Load type | F1: SS | G1: Load Value | H1: Load start | I1: Rs | J1: Vos,syst | M1: Start-time | O1: I_fet-I_L margin | Q1: I_g(hi/nom) | R1: I_g(low/nom)
B2: ='Design Calculator'!F69 -> 703.33333 | C2: ='Design Calculator'!F48 -> 86.666667 | D2: =IF( 'Design Calculator'!F71 = "Constant Current", "CC", "R") -> CC | F2: ='Design Calculator'!F73 -> Yes | G2: ='Design Calculator'!F72 -> 0 | H2: ='Design Calculator'!F70 -> 0 | I2: =RsEFF -> 0.3 | J2: ='Device Parameters'!E12 -> 0.001 | M2: =J114*1000 -> 32.5 | N2: ms | O2: =MIN(L10:L111) -> 1 | Q2: ='Device Parameters'!E30/'Device Parameters'!D30 -> 2 | R2: ='Device Parameters'!C30/'Device Parameters'!D30 -> 0.375
D4: To avoid timer running: Iload + Icap,ss < IFET_PLIM / 2 => SS_RATE < 1/Cout * (IFET_PLIM/2 - ILOAD) | M4: Max_SS_Rate | N4: =MIN(M10:M114) -> 1.7583333 | O4: V/ms | P4: max_power_typ | Q4: =MAX(O10:O114) -> 307.69231 | R4: W
M5: FET_ENERGY | N5: =SUM(N10:N114) -> 4.9519231 | O5: J | P5: max_power_high | Q5: =MAX(P10:P114) -> 615.38462 | R5: W
P6: max_power_low | Q6: =MAX(Q10:Q114) -> 115.38462 | R6: W
A7: VIN | B7: Vout | C7: ILOAD | D7: PLIM | E7: IFET_PLIM | F7: I_FET_SS | G7: IFET | H7: ICAP | I7: Dt | J7: Time | K7: Tiime (ms) | L7: I_Fet-IL margin | M7: Max _allowed SS_rate | N7: FET_Energy | O7: Power (W) | P7: P_ fast_SS | Q7: P_slow_SS
K8: -1 | O8: 0
K9: -0.01 | O9: 0
A10: =VINMAX -> 50 | B10: =VINMAX*((ROW()-10)/104) -> 0 | C10: =IF(B10>=$H$2,IF($D$2="CC", $G$2, B10/$G$2), 0) -> 0 | D10: =B2 -> 703.33333 | E10: =MIN(D10/(A10-B10),$C$2) -> 14.066667 | F10: =I_Cout_ss+C10 -> 6.1538462 | G10: =IF($F$2="YES", F10, E10) -> 6.1538462 | H10: =G10-C10 -> 6.1538462 | I10: =(COUTMAX/1000000)*(B10)/H10 -> 0 | J10: =I10 -> 0 | K10: =J10*1000 -> 0 | L10: =H10/G10 -> 1 | M10: =1/COUTMAX*(E10/2-C10)*1000 -> 1.7583333 | N10: =I10*G10*(A10-B10) -> 0 | O10: =G10*(A10-B10) -> 307.69231 | P10: =(A10-B10)*(I_Cout_ss*$Q$2+C10) -> 615.38462 | Q10: =(A10-B10)*(I_Cout_ss*$R$2+C10) -> 115.38462
A11: =VINMAX -> 50 | B11: =VINMAX*((ROW()-10)/104) -> 0.48076923 | C11: =IF(B11>=$H$2,IF($D$2="CC", $G$2, B11/$G$2), 0) -> 0 | D11: =B2 -> 703.33333 | E11: =MIN(D11/(A11-B11),$C$2) -> 14.203236 | F11: =I_Cout_ss+C11 -> 6.1538462 | G11: =IF($F$2="YES", F11, E11) -> 6.1538462 | H11: =G11-C11 -> 6.1538462 | I11: =(COUTMAX/1000000)*(B11-B10)/H11 -> 0.0003125 | J11: =J10+I11 -> 0.0003125 | K11: =J11*1000 -> 0.3125 | L11: =H11/G11 -> 1 | M11: =1/COUTMAX*(E11/2-C11)*1000 -> 1.7754045 | N11: =I11*G11*(A11-B11) -> 0.09522929 | O11: =G11*(A11-B11) -> 304.73373 | P11: =(A11-B11)*(I_Cout_ss*$Q$2+C11) -> 609.46746 | Q11: =(A11-B11)*(I_Cout_ss*$R$2+C11) -> 114.27515
A12: =VINMAX -> 50 | B12: =VINMAX*((ROW()-10)/104) -> 0.96153846 | C12: =IF(B12>=$H$2,IF($D$2="CC", $G$2, B12/$G$2), 0) -> 0 | D12: =B2 -> 703.33333 | E12: =MIN(D12/(A12-B12),$C$2) -> 14.342484 | F12: =I_Cout_ss+C12 -> 6.1538462 | G12: =IF($F$2="YES", F12, E12) -> 6.1538462 | H12: =G12-C12 -> 6.1538462 | I12: =(COUTMAX/1000000)*(B12-B11)/H12 -> 0.0003125 | J12: =J11+I12 -> 0.000625 | K12: =J12*1000 -> 0.625 | L12: =H12/G12 -> 1 | M12: =1/COUTMAX*(E12/2-C12)*1000 -> 1.7928105 | N12: =I12*G12*(A12-B12) -> 0.094304734 | O12: =G12*(A12-B12) -> 301.77515 | P12: =(A12-B12)*(I_Cout_ss*$Q$2+C12) -> 603.5503 | Q12: =(A12-B12)*(I_Cout_ss*$R$2+C12) -> 113.16568 | X12: Start-up slop
A13: =VINMAX -> 50 | B13: =VINMAX*((ROW()-10)/104) -> 1.4423077 | C13: =IF(B13>=$H$2,IF($D$2="CC", $G$2, B13/$G$2), 0) -> 0 | D13: =B2 -> 703.33333 | E13: =MIN(D13/(A13-B13),$C$2) -> 14.484488 | F13: =I_Cout_ss+C13 -> 6.1538462 | G13: =IF($F$2="YES", F13, E13) -> 6.1538462 | H13: =G13-C13 -> 6.1538462 | I13: =(COUTMAX/1000000)*(B13-B12)/H13 -> 0.0003125 | J13: =J12+I13 -> 0.0009375 | K13: =J13*1000 -> 0.9375 | L13: =H13/G13 -> 1 | M13: =1/COUTMAX*(E13/2-C13)*1000 -> 1.8105611 | N13: =I13*G13*(A13-B13) -> 0.093380178 | O13: =G13*(A13-B13) -> 298.81657 | P13: =(A13-B13)*(I_Cout_ss*$Q$2+C13) -> 597.63314 | Q13: =(A13-B13)*(I_Cout_ss*$R$2+C13) -> 112.05621 | X13: QG | Y13: 0.3
A14: =VINMAX -> 50 | B14: =VINMAX*((ROW()-10)/104) -> 1.9230769 | C14: =IF(B14>=$H$2,IF($D$2="CC", $G$2, B14/$G$2), 0) -> 0 | D14: =B2 -> 703.33333 | E14: =MIN(D14/(A14-B14),$C$2) -> 14.629333 | F14: =I_Cout_ss+C14 -> 6.1538462 | G14: =IF($F$2="YES", F14, E14) -> 6.1538462 | H14: =G14-C14 -> 6.1538462 | I14: =(COUTMAX/1000000)*(B14-B13)/H14 -> 0.0003125 | J14: =J13+I14 -> 0.00125 | K14: =J14*1000 -> 1.25 | L14: =H14/G14 -> 1 | M14: =1/COUTMAX*(E14/2-C14)*1000 -> 1.8286667 | N14: =I14*G14*(A14-B14) -> 0.092455621 | O14: =G14*(A14-B14) -> 295.85799 | P14: =(A14-B14)*(I_Cout_ss*$Q$2+C14) -> 591.71598 | Q14: =(A14-B14)*(I_Cout_ss*$R$2+C14) -> 110.94675 | X14: I_Src | Y14: 0.3
A15: =VINMAX -> 50 | B15: =VINMAX*((ROW()-10)/104) -> 2.4038462 | C15: =IF(B15>=$H$2,IF($D$2="CC", $G$2, B15/$G$2), 0) -> 0 | D15: =B2 -> 703.33333 | E15: =MIN(D15/(A15-B15),$C$2) -> 14.777104 | F15: =I_Cout_ss+C15 -> 6.1538462 | G15: =IF($F$2="YES", F15, E15) -> 6.1538462 | H15: =G15-C15 -> 6.1538462 | I15: =(COUTMAX/1000000)*(B15-B14)/H15 -> 0.0003125 | J15: =J14+I15 -> 0.0015625 | K15: =J15*1000 -> 1.5625 | L15: =H15/G15 -> 1 | M15: =1/COUTMAX*(E15/2-C15)*1000 -> 1.847138 | N15: =I15*G15*(A15-B15) -> 0.091531065 | O15: =G15*(A15-B15) -> 292.89941 | P15: =(A15-B15)*(I_Cout_ss*$Q$2+C15) -> 585.79882 | Q15: =(A15-B15)*(I_Cout_ss*$R$2+C15) -> 109.83728 | X15: RMS | Y15: =SQRT(Y14^2+Y13^2) -> 0.42426407
A16: =VINMAX -> 50 | B16: =VINMAX*((ROW()-10)/104) -> 2.8846154 | C16: =IF(B16>=$H$2,IF($D$2="CC", $G$2, B16/$G$2), 0) -> 0 | D16: =B2 -> 703.33333 | E16: =MIN(D16/(A16-B16),$C$2) -> 14.927891 | F16: =I_Cout_ss+C16 -> 6.1538462 | G16: =IF($F$2="YES", F16, E16) -> 6.1538462 | H16: =G16-C16 -> 6.1538462 | I16: =(COUTMAX/1000000)*(B16-B15)/H16 -> 0.0003125 | J16: =J15+I16 -> 0.001875 | K16: =J16*1000 -> 1.875 | L16: =H16/G16 -> 1 | M16: =1/COUTMAX*(E16/2-C16)*1000 -> 1.8659864 | N16: =I16*G16*(A16-B16) -> 0.090606509 | O16: =G16*(A16-B16) -> 289.94083 | P16: =(A16-B16)*(I_Cout_ss*$Q$2+C16) -> 579.88166 | Q16: =(A16-B16)*(I_Cout_ss*$R$2+C16) -> 108.72781
A17: =VINMAX -> 50 | B17: =VINMAX*((ROW()-10)/104) -> 3.3653846 | C17: =IF(B17>=$H$2,IF($D$2="CC", $G$2, B17/$G$2), 0) -> 0 | D17: =B2 -> 703.33333 | E17: =MIN(D17/(A17-B17),$C$2) -> 15.081787 | F17: =I_Cout_ss+C17 -> 6.1538462 | G17: =IF($F$2="YES", F17, E17) -> 6.1538462 | H17: =G17-C17 -> 6.1538462 | I17: =(COUTMAX/1000000)*(B17-B16)/H17 -> 0.0003125 | J17: =J16+I17 -> 0.0021875 | K17: =J17*1000 -> 2.1875 | L17: =H17/G17 -> 1 | M17: =1/COUTMAX*(E17/2-C17)*1000 -> 1.8852234 | N17: =I17*G17*(A17-B17) -> 0.089681953 | O17: =G17*(A17-B17) -> 286.98225 | P17: =(A17-B17)*(I_Cout_ss*$Q$2+C17) -> 573.9645 | Q17: =(A17-B17)*(I_Cout_ss*$R$2+C17) -> 107.61834 | X17: PLIM | Y17: 0.3
A18: =VINMAX -> 50 | B18: =VINMAX*((ROW()-10)/104) -> 3.8461538 | C18: =IF(B18>=$H$2,IF($D$2="CC", $G$2, B18/$G$2), 0) -> 0 | D18: =B2 -> 703.33333 | E18: =MIN(D18/(A18-B18),$C$2) -> 15.238889 | F18: =I_Cout_ss+C18 -> 6.1538462 | G18: =IF($F$2="YES", F18, E18) -> 6.1538462 | H18: =G18-C18 -> 6.1538462 | I18: =(COUTMAX/1000000)*(B18-B17)/H18 -> 0.0003125 | J18: =J17+I18 -> 0.0025 | K18: =J18*1000 -> 2.5 | L18: =H18/G18 -> 1 | M18: =1/COUTMAX*(E18/2-C18)*1000 -> 1.9048611 | N18: =I18*G18*(A18-B18) -> 0.088757396 | O18: =G18*(A18-B18) -> 284.02367 | P18: =(A18-B18)*(I_Cout_ss*$Q$2+C18) -> 568.04734 | Q18: =(A18-B18)*(I_Cout_ss*$R$2+C18) -> 106.50888 | X18: combined | Y18: =MAX(Y15:Y17) -> 0.42426407
A19: =VINMAX -> 50 | B19: =VINMAX*((ROW()-10)/104) -> 4.3269231 | C19: =IF(B19>=$H$2,IF($D$2="CC", $G$2, B19/$G$2), 0) -> 0 | D19: =B2 -> 703.33333 | E19: =MIN(D19/(A19-B19),$C$2) -> 15.399298 | F19: =I_Cout_ss+C19 -> 6.1538462 | G19: =IF($F$2="YES", F19, E19) -> 6.1538462 | H19: =G19-C19 -> 6.1538462 | I19: =(COUTMAX/1000000)*(B19-B18)/H19 -> 0.0003125 | J19: =J18+I19 -> 0.0028125 | K19: =J19*1000 -> 2.8125 | L19: =H19/G19 -> 1 | M19: =1/COUTMAX*(E19/2-C19)*1000 -> 1.9249123 | N19: =I19*G19*(A19-B19) -> 0.08783284 | O19: =G19*(A19-B19) -> 281.06509 | P19: =(A19-B19)*(I_Cout_ss*$Q$2+C19) -> 562.13018 | Q19: =(A19-B19)*(I_Cout_ss*$R$2+C19) -> 105.39941
A20: =VINMAX -> 50 | B20: =VINMAX*((ROW()-10)/104) -> 4.8076923 | C20: =IF(B20>=$H$2,IF($D$2="CC", $G$2, B20/$G$2), 0) -> 0 | D20: =B2 -> 703.33333 | E20: =MIN(D20/(A20-B20),$C$2) -> 15.563121 | F20: =I_Cout_ss+C20 -> 6.1538462 | G20: =IF($F$2="YES", F20, E20) -> 6.1538462 | H20: =G20-C20 -> 6.1538462 | I20: =(COUTMAX/1000000)*(B20-B19)/H20 -> 0.0003125 | J20: =J19+I20 -> 0.003125 | K20: =J20*1000 -> 3.125 | L20: =H20/G20 -> 1 | M20: =1/COUTMAX*(E20/2-C20)*1000 -> 1.9453901 | N20: =I20*G20*(A20-B20) -> 0.086908284 | O20: =G20*(A20-B20) -> 278.10651 | P20: =(A20-B20)*(I_Cout_ss*$Q$2+C20) -> 556.21302 | Q20: =(A20-B20)*(I_Cout_ss*$R$2+C20) -> 104.28994 | X20: I_timer | Y20: 0.2
A21: =VINMAX -> 50 | B21: =VINMAX*((ROW()-10)/104) -> 5.2884615 | C21: =IF(B21>=$H$2,IF($D$2="CC", $G$2, B21/$G$2), 0) -> 0 | D21: =B2 -> 703.33333 | E21: =MIN(D21/(A21-B21),$C$2) -> 15.730466 | F21: =I_Cout_ss+C21 -> 6.1538462 | G21: =IF($F$2="YES", F21, E21) -> 6.1538462 | H21: =G21-C21 -> 6.1538462 | I21: =(COUTMAX/1000000)*(B21-B20)/H21 -> 0.0003125 | J21: =J20+I21 -> 0.0034375 | K21: =J21*1000 -> 3.4375 | L21: =H21/G21 -> 1 | M21: =1/COUTMAX*(E21/2-C21)*1000 -> 1.9663082 | N21: =I21*G21*(A21-B21) -> 0.085983728 | O21: =G21*(A21-B21) -> 275.14793 | P21: =(A21-B21)*(I_Cout_ss*$Q$2+C21) -> 550.29586 | Q21: =(A21-B21)*(I_Cout_ss*$R$2+C21) -> 103.18047 | X21: C_timer | Y21: 0.2
A22: =VINMAX -> 50 | B22: =VINMAX*((ROW()-10)/104) -> 5.7692308 | C22: =IF(B22>=$H$2,IF($D$2="CC", $G$2, B22/$G$2), 0) -> 0 | D22: =B2 -> 703.33333 | E22: =MIN(D22/(A22-B22),$C$2) -> 15.901449 | F22: =I_Cout_ss+C22 -> 6.1538462 | G22: =IF($F$2="YES", F22, E22) -> 6.1538462 | H22: =G22-C22 -> 6.1538462 | I22: =(COUTMAX/1000000)*(B22-B21)/H22 -> 0.0003125 | J22: =J21+I22 -> 0.00375 | K22: =J22*1000 -> 3.75 | L22: =H22/G22 -> 1 | M22: =1/COUTMAX*(E22/2-C22)*1000 -> 1.9876812 | N22: =I22*G22*(A22-B22) -> 0.085059172 | O22: =G22*(A22-B22) -> 272.18935 | P22: =(A22-B22)*(I_Cout_ss*$Q$2+C22) -> 544.3787 | Q22: =(A22-B22)*(I_Cout_ss*$R$2+C22) -> 102.07101 | X22: RMS | Y22: =SQRT(Y21^2+Y20^2) -> 0.28284271
A23: =VINMAX -> 50 | B23: =VINMAX*((ROW()-10)/104) -> 6.25 | C23: =IF(B23>=$H$2,IF($D$2="CC", $G$2, B23/$G$2), 0) -> 0 | D23: =B2 -> 703.33333 | E23: =MIN(D23/(A23-B23),$C$2) -> 16.07619 | F23: =I_Cout_ss+C23 -> 6.1538462 | G23: =IF($F$2="YES", F23, E23) -> 6.1538462 | H23: =G23-C23 -> 6.1538462 | I23: =(COUTMAX/1000000)*(B23-B22)/H23 -> 0.0003125 | J23: =J22+I23 -> 0.0040625 | K23: =J23*1000 -> 4.0625 | L23: =H23/G23 -> 1 | M23: =1/COUTMAX*(E23/2-C23)*1000 -> 2.0095238 | N23: =I23*G23*(A23-B23) -> 0.084134615 | O23: =G23*(A23-B23) -> 269.23077 | P23: =(A23-B23)*(I_Cout_ss*$Q$2+C23) -> 538.46154 | Q23: =(A23-B23)*(I_Cout_ss*$R$2+C23) -> 100.96154
A24: =VINMAX -> 50 | B24: =VINMAX*((ROW()-10)/104) -> 6.7307692 | C24: =IF(B24>=$H$2,IF($D$2="CC", $G$2, B24/$G$2), 0) -> 0 | D24: =B2 -> 703.33333 | E24: =MIN(D24/(A24-B24),$C$2) -> 16.254815 | F24: =I_Cout_ss+C24 -> 6.1538462 | G24: =IF($F$2="YES", F24, E24) -> 6.1538462 | H24: =G24-C24 -> 6.1538462 | I24: =(COUTMAX/1000000)*(B24-B23)/H24 -> 0.0003125 | J24: =J23+I24 -> 0.004375 | K24: =J24*1000 -> 4.375 | L24: =H24/G24 -> 1 | M24: =1/COUTMAX*(E24/2-C24)*1000 -> 2.0318519 | N24: =I24*G24*(A24-B24) -> 0.083210059 | O24: =G24*(A24-B24) -> 266.27219 | P24: =(A24-B24)*(I_Cout_ss*$Q$2+C24) -> 532.54438 | Q24: =(A24-B24)*(I_Cout_ss*$R$2+C24) -> 99.852071 | X24: Final | Y24: =SQRT(Y18^2+Y22^2) -> 0.50990195
A25: =VINMAX -> 50 | B25: =VINMAX*((ROW()-10)/104) -> 7.2115385 | C25: =IF(B25>=$H$2,IF($D$2="CC", $G$2, B25/$G$2), 0) -> 0 | D25: =B2 -> 703.33333 | E25: =MIN(D25/(A25-B25),$C$2) -> 16.437453 | F25: =I_Cout_ss+C25 -> 6.1538462 | G25: =IF($F$2="YES", F25, E25) -> 6.1538462 | H25: =G25-C25 -> 6.1538462 | I25: =(COUTMAX/1000000)*(B25-B24)/H25 -> 0.0003125 | J25: =J24+I25 -> 0.0046875 | K25: =J25*1000 -> 4.6875 | L25: =H25/G25 -> 1 | M25: =1/COUTMAX*(E25/2-C25)*1000 -> 2.0546816 | N25: =I25*G25*(A25-B25) -> 0.082285503 | O25: =G25*(A25-B25) -> 263.31361 | P25: =(A25-B25)*(I_Cout_ss*$Q$2+C25) -> 526.62722 | Q25: =(A25-B25)*(I_Cout_ss*$R$2+C25) -> 98.742604
A26: =VINMAX -> 50 | B26: =VINMAX*((ROW()-10)/104) -> 7.6923077 | C26: =IF(B26>=$H$2,IF($D$2="CC", $G$2, B26/$G$2), 0) -> 0 | D26: =B2 -> 703.33333 | E26: =MIN(D26/(A26-B26),$C$2) -> 16.624242 | F26: =I_Cout_ss+C26 -> 6.1538462 | G26: =IF($F$2="YES", F26, E26) -> 6.1538462 | H26: =G26-C26 -> 6.1538462 | I26: =(COUTMAX/1000000)*(B26-B25)/H26 -> 0.0003125 | J26: =J25+I26 -> 0.005 | K26: =J26*1000 -> 5 | L26: =H26/G26 -> 1 | M26: =1/COUTMAX*(E26/2-C26)*1000 -> 2.0780303 | N26: =I26*G26*(A26-B26) -> 0.081360947 | O26: =G26*(A26-B26) -> 260.35503 | P26: =(A26-B26)*(I_Cout_ss*$Q$2+C26) -> 520.71006 | Q26: =(A26-B26)*(I_Cout_ss*$R$2+C26) -> 97.633136
A27: =VINMAX -> 50 | B27: =VINMAX*((ROW()-10)/104) -> 8.1730769 | C27: =IF(B27>=$H$2,IF($D$2="CC", $G$2, B27/$G$2), 0) -> 0 | D27: =B2 -> 703.33333 | E27: =MIN(D27/(A27-B27),$C$2) -> 16.815326 | F27: =I_Cout_ss+C27 -> 6.1538462 | G27: =IF($F$2="YES", F27, E27) -> 6.1538462 | H27: =G27-C27 -> 6.1538462 | I27: =(COUTMAX/1000000)*(B27-B26)/H27 -> 0.0003125 | J27: =J26+I27 -> 0.0053125 | K27: =J27*1000 -> 5.3125 | L27: =H27/G27 -> 1 | M27: =1/COUTMAX*(E27/2-C27)*1000 -> 2.1019157 | N27: =I27*G27*(A27-B27) -> 0.080436391 | O27: =G27*(A27-B27) -> 257.39645 | P27: =(A27-B27)*(I_Cout_ss*$Q$2+C27) -> 514.7929 | Q27: =(A27-B27)*(I_Cout_ss*$R$2+C27) -> 96.523669
A28: =VINMAX -> 50 | B28: =VINMAX*((ROW()-10)/104) -> 8.6538462 | C28: =IF(B28>=$H$2,IF($D$2="CC", $G$2, B28/$G$2), 0) -> 0 | D28: =B2 -> 703.33333 | E28: =MIN(D28/(A28-B28),$C$2) -> 17.010853 | F28: =I_Cout_ss+C28 -> 6.1538462 | G28: =IF($F$2="YES", F28, E28) -> 6.1538462 | H28: =G28-C28 -> 6.1538462 | I28: =(COUTMAX/1000000)*(B28-B27)/H28 -> 0.0003125 | J28: =J27+I28 -> 0.005625 | K28: =J28*1000 -> 5.625 | L28: =H28/G28 -> 1 | M28: =1/COUTMAX*(E28/2-C28)*1000 -> 2.1263566 | N28: =I28*G28*(A28-B28) -> 0.079511834 | O28: =G28*(A28-B28) -> 254.43787 | P28: =(A28-B28)*(I_Cout_ss*$Q$2+C28) -> 508.87574 | Q28: =(A28-B28)*(I_Cout_ss*$R$2+C28) -> 95.414201
A29: =VINMAX -> 50 | B29: =VINMAX*((ROW()-10)/104) -> 9.1346154 | C29: =IF(B29>=$H$2,IF($D$2="CC", $G$2, B29/$G$2), 0) -> 0 | D29: =B2 -> 703.33333 | E29: =MIN(D29/(A29-B29),$C$2) -> 17.21098 | F29: =I_Cout_ss+C29 -> 6.1538462 | G29: =IF($F$2="YES", F29, E29) -> 6.1538462 | H29: =G29-C29 -> 6.1538462 | I29: =(COUTMAX/1000000)*(B29-B28)/H29 -> 0.0003125 | J29: =J28+I29 -> 0.0059375 | K29: =J29*1000 -> 5.9375 | L29: =H29/G29 -> 1 | M29: =1/COUTMAX*(E29/2-C29)*1000 -> 2.1513725 | N29: =I29*G29*(A29-B29) -> 0.078587278 | O29: =G29*(A29-B29) -> 251.47929 | P29: =(A29-B29)*(I_Cout_ss*$Q$2+C29) -> 502.95858 | Q29: =(A29-B29)*(I_Cout_ss*$R$2+C29) -> 94.304734
A30: =VINMAX -> 50 | B30: =VINMAX*((ROW()-10)/104) -> 9.6153846 | C30: =IF(B30>=$H$2,IF($D$2="CC", $G$2, B30/$G$2), 0) -> 0 | D30: =B2 -> 703.33333 | E30: =MIN(D30/(A30-B30),$C$2) -> 17.415873 | F30: =I_Cout_ss+C30 -> 6.1538462 | G30: =IF($F$2="YES", F30, E30) -> 6.1538462 | H30: =G30-C30 -> 6.1538462 | I30: =(COUTMAX/1000000)*(B30-B29)/H30 -> 0.0003125 | J30: =J29+I30 -> 0.00625 | K30: =J30*1000 -> 6.25 | L30: =H30/G30 -> 1 | M30: =1/COUTMAX*(E30/2-C30)*1000 -> 2.1769841 | N30: =I30*G30*(A30-B30) -> 0.077662722 | O30: =G30*(A30-B30) -> 248.52071 | P30: =(A30-B30)*(I_Cout_ss*$Q$2+C30) -> 497.04142 | Q30: =(A30-B30)*(I_Cout_ss*$R$2+C30) -> 93.195266
A31: =VINMAX -> 50 | B31: =VINMAX*((ROW()-10)/104) -> 10.096154 | C31: =IF(B31>=$H$2,IF($D$2="CC", $G$2, B31/$G$2), 0) -> 0 | D31: =B2 -> 703.33333 | E31: =MIN(D31/(A31-B31),$C$2) -> 17.625703 | F31: =I_Cout_ss+C31 -> 6.1538462 | G31: =IF($F$2="YES", F31, E31) -> 6.1538462 | H31: =G31-C31 -> 6.1538462 | I31: =(COUTMAX/1000000)*(B31-B30)/H31 -> 0.0003125 | J31: =J30+I31 -> 0.0065625 | K31: =J31*1000 -> 6.5625 | L31: =H31/G31 -> 1 | M31: =1/COUTMAX*(E31/2-C31)*1000 -> 2.2032129 | N31: =I31*G31*(A31-B31) -> 0.076738166 | O31: =G31*(A31-B31) -> 245.56213 | P31: =(A31-B31)*(I_Cout_ss*$Q$2+C31) -> 491.12426 | Q31: =(A31-B31)*(I_Cout_ss*$R$2+C31) -> 92.085799
A32: =VINMAX -> 50 | B32: =VINMAX*((ROW()-10)/104) -> 10.576923 | C32: =IF(B32>=$H$2,IF($D$2="CC", $G$2, B32/$G$2), 0) -> 0 | D32: =B2 -> 703.33333 | E32: =MIN(D32/(A32-B32),$C$2) -> 17.84065 | F32: =I_Cout_ss+C32 -> 6.1538462 | G32: =IF($F$2="YES", F32, E32) -> 6.1538462 | H32: =G32-C32 -> 6.1538462 | I32: =(COUTMAX/1000000)*(B32-B31)/H32 -> 0.0003125 | J32: =J31+I32 -> 0.006875 | K32: =J32*1000 -> 6.875 | L32: =H32/G32 -> 1 | M32: =1/COUTMAX*(E32/2-C32)*1000 -> 2.2300813 | N32: =I32*G32*(A32-B32) -> 0.075813609 | O32: =G32*(A32-B32) -> 242.60355 | P32: =(A32-B32)*(I_Cout_ss*$Q$2+C32) -> 485.2071 | Q32: =(A32-B32)*(I_Cout_ss*$R$2+C32) -> 90.976331
A33: =VINMAX -> 50 | B33: =VINMAX*((ROW()-10)/104) -> 11.057692 | C33: =IF(B33>=$H$2,IF($D$2="CC", $G$2, B33/$G$2), 0) -> 0 | D33: =B2 -> 703.33333 | E33: =MIN(D33/(A33-B33),$C$2) -> 18.060905 | F33: =I_Cout_ss+C33 -> 6.1538462 | G33: =IF($F$2="YES", F33, E33) -> 6.1538462 | H33: =G33-C33 -> 6.1538462 | I33: =(COUTMAX/1000000)*(B33-B32)/H33 -> 0.0003125 | J33: =J32+I33 -> 0.0071875 | K33: =J33*1000 -> 7.1875 | L33: =H33/G33 -> 1 | M33: =1/COUTMAX*(E33/2-C33)*1000 -> 2.2576132 | N33: =I33*G33*(A33-B33) -> 0.074889053 | O33: =G33*(A33-B33) -> 239.64497 | P33: =(A33-B33)*(I_Cout_ss*$Q$2+C33) -> 479.28994 | Q33: =(A33-B33)*(I_Cout_ss*$R$2+C33) -> 89.866864
A34: =VINMAX -> 50 | B34: =VINMAX*((ROW()-10)/104) -> 11.538462 | C34: =IF(B34>=$H$2,IF($D$2="CC", $G$2, B34/$G$2), 0) -> 0 | D34: =B2 -> 703.33333 | E34: =MIN(D34/(A34-B34),$C$2) -> 18.286667 | F34: =I_Cout_ss+C34 -> 6.1538462 | G34: =IF($F$2="YES", F34, E34) -> 6.1538462 | H34: =G34-C34 -> 6.1538462 | I34: =(COUTMAX/1000000)*(B34-B33)/H34 -> 0.0003125 | J34: =J33+I34 -> 0.0075 | K34: =J34*1000 -> 7.5 | L34: =H34/G34 -> 1 | M34: =1/COUTMAX*(E34/2-C34)*1000 -> 2.2858333 | N34: =I34*G34*(A34-B34) -> 0.073964497 | O34: =G34*(A34-B34) -> 236.68639 | P34: =(A34-B34)*(I_Cout_ss*$Q$2+C34) -> 473.37278 | Q34: =(A34-B34)*(I_Cout_ss*$R$2+C34) -> 88.757396
A35: =VINMAX -> 50 | B35: =VINMAX*((ROW()-10)/104) -> 12.019231 | C35: =IF(B35>=$H$2,IF($D$2="CC", $G$2, B35/$G$2), 0) -> 0 | D35: =B2 -> 703.33333 | E35: =MIN(D35/(A35-B35),$C$2) -> 18.518143 | F35: =I_Cout_ss+C35 -> 6.1538462 | G35: =IF($F$2="YES", F35, E35) -> 6.1538462 | H35: =G35-C35 -> 6.1538462 | I35: =(COUTMAX/1000000)*(B35-B34)/H35 -> 0.0003125 | J35: =J34+I35 -> 0.0078125 | K35: =J35*1000 -> 7.8125 | L35: =H35/G35 -> 1 | M35: =1/COUTMAX*(E35/2-C35)*1000 -> 2.3147679 | N35: =I35*G35*(A35-B35) -> 0.073039941 | O35: =G35*(A35-B35) -> 233.72781 | P35: =(A35-B35)*(I_Cout_ss*$Q$2+C35) -> 467.45562 | Q35: =(A35-B35)*(I_Cout_ss*$R$2+C35) -> 87.647929
A36: =VINMAX -> 50 | B36: =VINMAX*((ROW()-10)/104) -> 12.5 | C36: =IF(B36>=$H$2,IF($D$2="CC", $G$2, B36/$G$2), 0) -> 0 | D36: =B2 -> 703.33333 | E36: =MIN(D36/(A36-B36),$C$2) -> 18.755556 | F36: =I_Cout_ss+C36 -> 6.1538462 | G36: =IF($F$2="YES", F36, E36) -> 6.1538462 | H36: =G36-C36 -> 6.1538462 | I36: =(COUTMAX/1000000)*(B36-B35)/H36 -> 0.0003125 | J36: =J35+I36 -> 0.008125 | K36: =J36*1000 -> 8.125 | L36: =H36/G36 -> 1 | M36: =1/COUTMAX*(E36/2-C36)*1000 -> 2.3444444 | N36: =I36*G36*(A36-B36) -> 0.072115385 | O36: =G36*(A36-B36) -> 230.76923 | P36: =(A36-B36)*(I_Cout_ss*$Q$2+C36) -> 461.53846 | Q36: =(A36-B36)*(I_Cout_ss*$R$2+C36) -> 86.538462
A37: =VINMAX -> 50 | B37: =VINMAX*((ROW()-10)/104) -> 12.980769 | C37: =IF(B37>=$H$2,IF($D$2="CC", $G$2, B37/$G$2), 0) -> 0 | D37: =B2 -> 703.33333 | E37: =MIN(D37/(A37-B37),$C$2) -> 18.999134 | F37: =I_Cout_ss+C37 -> 6.1538462 | G37: =IF($F$2="YES", F37, E37) -> 6.1538462 | H37: =G37-C37 -> 6.1538462 | I37: =(COUTMAX/1000000)*(B37-B36)/H37 -> 0.0003125 | J37: =J36+I37 -> 0.0084375 | K37: =J37*1000 -> 8.4375 | L37: =H37/G37 -> 1 | M37: =1/COUTMAX*(E37/2-C37)*1000 -> 2.3748918 | N37: =I37*G37*(A37-B37) -> 0.071190828 | O37: =G37*(A37-B37) -> 227.81065 | P37: =(A37-B37)*(I_Cout_ss*$Q$2+C37) -> 455.6213 | Q37: =(A37-B37)*(I_Cout_ss*$R$2+C37) -> 85.428994
A38: =VINMAX -> 50 | B38: =VINMAX*((ROW()-10)/104) -> 13.461538 | C38: =IF(B38>=$H$2,IF($D$2="CC", $G$2, B38/$G$2), 0) -> 0 | D38: =B2 -> 703.33333 | E38: =MIN(D38/(A38-B38),$C$2) -> 19.249123 | F38: =I_Cout_ss+C38 -> 6.1538462 | G38: =IF($F$2="YES", F38, E38) -> 6.1538462 | H38: =G38-C38 -> 6.1538462 | I38: =(COUTMAX/1000000)*(B38-B37)/H38 -> 0.0003125 | J38: =J37+I38 -> 0.00875 | K38: =J38*1000 -> 8.75 | L38: =H38/G38 -> 1 | M38: =1/COUTMAX*(E38/2-C38)*1000 -> 2.4061404 | N38: =I38*G38*(A38-B38) -> 0.070266272 | O38: =G38*(A38-B38) -> 224.85207 | P38: =(A38-B38)*(I_Cout_ss*$Q$2+C38) -> 449.70414 | Q38: =(A38-B38)*(I_Cout_ss*$R$2+C38) -> 84.319527
A39: =VINMAX -> 50 | B39: =VINMAX*((ROW()-10)/104) -> 13.942308 | C39: =IF(B39>=$H$2,IF($D$2="CC", $G$2, B39/$G$2), 0) -> 0 | D39: =B2 -> 703.33333 | E39: =MIN(D39/(A39-B39),$C$2) -> 19.505778 | F39: =I_Cout_ss+C39 -> 6.1538462 | G39: =IF($F$2="YES", F39, E39) -> 6.1538462 | H39: =G39-C39 -> 6.1538462 | I39: =(COUTMAX/1000000)*(B39-B38)/H39 -> 0.0003125 | J39: =J38+I39 -> 0.0090625 | K39: =J39*1000 -> 9.0625 | L39: =H39/G39 -> 1 | M39: =1/COUTMAX*(E39/2-C39)*1000 -> 2.4382222 | N39: =I39*G39*(A39-B39) -> 0.069341716 | O39: =G39*(A39-B39) -> 221.89349 | P39: =(A39-B39)*(I_Cout_ss*$Q$2+C39) -> 443.78698 | Q39: =(A39-B39)*(I_Cout_ss*$R$2+C39) -> 83.210059
A40: =VINMAX -> 50 | B40: =VINMAX*((ROW()-10)/104) -> 14.423077 | C40: =IF(B40>=$H$2,IF($D$2="CC", $G$2, B40/$G$2), 0) -> 0 | D40: =B2 -> 703.33333 | E40: =MIN(D40/(A40-B40),$C$2) -> 19.769369 | F40: =I_Cout_ss+C40 -> 6.1538462 | G40: =IF($F$2="YES", F40, E40) -> 6.1538462 | H40: =G40-C40 -> 6.1538462 | I40: =(COUTMAX/1000000)*(B40-B39)/H40 -> 0.0003125 | J40: =J39+I40 -> 0.009375 | K40: =J40*1000 -> 9.375 | L40: =H40/G40 -> 1 | M40: =1/COUTMAX*(E40/2-C40)*1000 -> 2.4711712 | N40: =I40*G40*(A40-B40) -> 0.06841716 | O40: =G40*(A40-B40) -> 218.93491 | P40: =(A40-B40)*(I_Cout_ss*$Q$2+C40) -> 437.86982 | Q40: =(A40-B40)*(I_Cout_ss*$R$2+C40) -> 82.100592
A41: =VINMAX -> 50 | B41: =VINMAX*((ROW()-10)/104) -> 14.903846 | C41: =IF(B41>=$H$2,IF($D$2="CC", $G$2, B41/$G$2), 0) -> 0 | D41: =B2 -> 703.33333 | E41: =MIN(D41/(A41-B41),$C$2) -> 20.040183 | F41: =I_Cout_ss+C41 -> 6.1538462 | G41: =IF($F$2="YES", F41, E41) -> 6.1538462 | H41: =G41-C41 -> 6.1538462 | I41: =(COUTMAX/1000000)*(B41-B40)/H41 -> 0.0003125 | J41: =J40+I41 -> 0.0096875 | K41: =J41*1000 -> 9.6875 | L41: =H41/G41 -> 1 | M41: =1/COUTMAX*(E41/2-C41)*1000 -> 2.5050228 | N41: =I41*G41*(A41-B41) -> 0.067492604 | O41: =G41*(A41-B41) -> 215.97633 | P41: =(A41-B41)*(I_Cout_ss*$Q$2+C41) -> 431.95266 | Q41: =(A41-B41)*(I_Cout_ss*$R$2+C41) -> 80.991124
...

Sheet SOA
C2: Look Up | H2: I = a * t^m
B3: 100us | C3: 1ms | D3: 10ms | E3: 100ms | F3: 1s/DC | H3: a = iSOA1/tSOA1^m
A4: Final SOA | B4: ='Design Calculator'!AN58 -> 300 | C4: ='Design Calculator'!$AN$59 -> 81 | D4: ='Design Calculator'!$AN$60 -> 18 | E4: =IF('Design Calculator'!$AN$61 = "NA", F4, 'Design Calculator'!$AN$61) -> 6.3 | F4: ='Design Calculator'!AN62 -> 4.5 | H4: m = log(iSOA1/iSOA2)/log(tSOA1/tSOA2)
B7: SOA Check - Based on Timer | G7: SOA Predictor - dv/dt start-up
B8: time | C8: =IF('Design Calculator'!F73="No", 'Design Calculator'!$F$79,'Design Calculator'!F92) -> 0.52 | D8: ms | G8: time | H8: =Equations!F60 -> 16.09375
B9: Voltage | C9: =VINMAX -> 50 | D9: V | G9: Voltage | H9: =VINMAX -> 50
B10: Lower time | C10: =IF(C8<10, IF(C8<1, 0.1, 1), IF(C8<100, 10, 100)) -> 0.1 | D10: ms | G10: Lower time | H10: =IF(H8<10, IF(H8<1, 0.1, 1), IF(H8<100, 10, 100)) -> 10
B11: Lower time (adjusted) | C11: =IF('Design Calculator'!F61="NA", MIN(SOA!C10,1),SOA!C10) -> 0.1 | G11: Lower time (adjusted) | H11: =IF('Design Calculator'!F61="NA", MIN(SOA!H10,1),SOA!H10) -> 10
B12: Higher timer | C12: =C10*10 -> 1 | D12: ms | G12: Higher time | H12: =H10*10 -> 100
B13: Higher time (adjusted) | C13: =IF('Design Calculator'!F62="NA", MIN(SOA!C12,10),SOA!C12) -> 1 | G13: Higher time (adjusted) | H13: =IF('Design Calculator'!F62="NA", MIN(SOA!H12,10),SOA!H12) -> 100
B14: I (lower time) | C14: =IF(C10=0.1, B4, IF(C10=1, C4, IF(C10=10, D4, E4))) -> 300 | D14: A | G14: I (lower time) | H14: =IF(H11=0.1, B4, IF(H11=1, C4, IF(H11=10, D4, E4))) -> 18
B15: I (higher time) | C15: =IF(C12=1000, F4, IF(C12=1, C4, IF(C12=10, D4, E4))) -> 81 | D15: A | G15: I (higher time) | H15: =IF(H13=1000, F4, IF(H13=1, C4, IF(H13=10, D4, E4))) -> 6.3
B17: Assuming Power vs time is linear on a log-log plot | G17: Assuming Power vs time is linear on a log-log plot
B18: a | C18: =C14/C11^C19 -> 81 | G18: a | H18: =H14/H11^H19 -> 51.428571
B19: m | C19: =LOG(C14/C15)/LOG(C11/C13) -> -0.56863624 | G19: m | H19: =IF(H14=H15,0.000000000001,LOG(H14/H15)/LOG(H11/H13)) -> -0.45593196 | I19: <-- Cannot plot zero on a log graph. If slope ~=0, then use 1e-12 as value
B20: Extr. I | C20: =C18*C8^C19 -> 117.48321 | D20: A | G20: Extr. I | H20: =H18*H8^H19 -> 14.489415
B22: Interpolated Power= | C22: =C20*C9 -> 5874.1606 | G22: Interpolated Power= | H22: =H20*H9 -> 724.47077
G24: board hot? | H24: ='Design Calculator'!F81 -> No
B25: Derating factor = | C25: =(TJMAX-TJ)/(TJMAX-25) -> 0.24803765 | G25: Temp for derating | H25: =IF(H24="Yes", TJ,TAMB) -> 85
B26: Max Power with Temp Derating = | C26: =IF((C22*C25)<0,0.000000001,C22*C25) -> 1457.013 | D26: W
G27: Derating factor = | H27: =(TJMAX-H25)/(TJMAX-25) -> 0.85882353
G28: Max Power with Temp Derating = | H28: =IF((H22*H27)<0,0.000000001,H22*H27) -> 622.19254
B29: SOA Coefficients
C30: 0.1 to 1 ms | D30: 1 to 10ms | E30: 10ms to 100 ms | F30: 100 ms to 1s
B31: t1 | C31: 0.1 | D31: 1 | E31: 10 | F31: 100
B32: t2 | C32: 1 | D32: 10 | E32: 100 | F32: 1000
B33: a | C33: =B4/(C31^C34) -> 81 | D33: =C4/(D31^D34) -> 81 | E33: =IF('Design Calculator'!F62="NA",D33,D4/(E31^E34)) -> 51.428571 | F33: =IF('Design Calculator'!F62="NA", E33, E4/(F31^F34)) -> 12.348
B34: m | C34: =LOG(B4/C4)/LOG(C31/C32) -> -0.56863624 | D34: =LOG(C4/D4)/LOG(D31/D32) -> -0.65321251 | E34: =IF('Design Calculator'!F62="NA", D34, LOG(D4/E4)/LOG(E31/E32)) -> -0.45593196 | F34: =IF('Design Calculator'!F62="NA",E34,LOG(E4/F4)/LOG(F31/F32)) -> -0.14612804

Sheet dv_dt_recommendations
C5: Key Equations for SOA margin estimate:
C7: 1) Get total Energy = 1/2 CV^2 + E_load (t_worksheet) * t_start / t_ worksheet
C8: note: t_worksheet is the start time from the start-up worksheet. E_load = Total Energy @ Start-up - 1/2CV^2
C10: 2) Get peak power: 4 Possible points with peak power
C11: a) At Vin = 0 [mainly if there is no load or constant current load that starts at Vout = 0=
C12: b) At Vin = Load start [ constant current=
C13: c) When derivative of power = 0 [Peak, applies to resistive loads only=
D14: P = (I_cap + Vout/R ) * (Vin - Vout) = Icap * Vin - Icap * Vout +Vin * Vout / R - Vout^2 / R
D15: => dP/dVout = -Icap + Vin/R -2Vout /R ; Zero when Vout = -R*I_cap / 2 + Vin / 2
D18: Copied Inputs
D19: Temp_start_up | E19: =SOA!H25 -> 85
D20: SOA margin target | E20: 1.5 | I20: SOA Coefficients
D21: Cap Energy (J) | E21: =1/2*COUTMAX*VINMAX^2*0.000001 -> 5 | J21: 0.1 to 1 ms | K21: 1 to 10ms | L21: 10ms to 100 ms | M21: 100 ms to 1s
D22: E_load (t_worksheet) (J) | E22: =MAX(Equations!F58-E21,0) -> 0 | I22: t1 | J22: 0.1 | K22: 1 | L22: 10 | M22: 100
D23: t_worksheet (ms) | E23: =Equations!F57 -> 32.5 | I23: t2 | J23: 1 | K23: 10 | L23: 100 | M23: 1000
I24: a | J24: =SOA!C33 -> 81 | K24: =SOA!D33 -> 81 | L24: =SOA!E33 -> 51.428571 | M24: =SOA!F33 -> 12.348
D25: Load Turn-On Threshold | E25: ='Design Calculator'!F70 -> 0 | I25: m | J25: =SOA!C34 -> -0.56863624 | K25: =SOA!D34 -> -0.65321251 | L25: =SOA!E34 -> -0.45593196 | M25: =SOA!F34 -> -0.14612804
D26: Startup Load Type | E26: ='Design Calculator'!F71 -> Constant Current
D27: Startup Load Value | E27: ='Design Calculator'!F72 -> 0 | I27: Initial | J27: Final
G28: max slew rate | I28: =SUM(E58:X58) -> 2.1995769 | J28: =IF(I28=0, "NA", I28/AVERAGE(1, E32)) -> 2.4648433
D29: Upper bound Slew Rate (4ms start-up) (V/ms) | E29: =12/1 -> 12 | G29: min slew rate | I29: =SUM(E59:X59) -> 0.12 | J29: =IF(I29=0, "NA", I29*AVERAGE(1,E32)) -> 0.1070856
D30: Min Slew Rate (400 ms start - up) (V/ms) | E30: 0.12
D31: # of points | E31: 20
D32: mult per point | E32: =(E30/E29)^(1/(E31-1)) -> 0.78475997
E34: 1 | F34: 2 | G34: 3 | H34: 4 | I34: 5 | J34: 6 | K34: 7 | L34: 8 | M34: 9 | N34: 10 | O34: 11 | P34: 12 | Q34: 13 | R34: 14 | S34: 15 | T34: 16 | U34: 17 | V34: 18 | W34: 19 | X34: 20
D35: slew rate (V/ms) | E35: =E29 -> 12 | F35: =E35*$E$32 -> 9.4171196 | G35: =F35*$E$32 -> 7.3901785 | H35: =G35*$E$32 -> 5.7995163 | I35: =H35*$E$32 -> 4.5512282 | J35: =I35*$E$32 -> 3.5716217 | K35: =J35*$E$32 -> 2.8028658 | L35: =K35*$E$32 -> 2.1995769 | M35: =L35*$E$32 -> 1.7261399 | ... X35: =W35*$E$32 -> 0.12
D36: t_start (ms) | E36: =VINMAX/E35 -> 4.1666667 | F36: =VINMAX/F35 -> 5.3094791 | G36: =VINMAX/G35 -> 6.7657364 | H36: =VINMAX/H35 -> 8.6214087 | I36: =VINMAX/I35 -> 10.986045 | J36: =VINMAX/J35 -> 13.999243 | K36: =VINMAX/K35 -> 17.838885 | L36: =VINMAX/L35 -> 22.731645 | ... X36: =VINMAX/X35 -> 416.66667
D37: I_cap (A) | E37: =E35*COUTMAX/1000 -> 48 | F37: =F35*COUTMAX/1000 -> 37.668479 | G37: =G35*COUTMAX/1000 -> 29.560714 | H37: =H35*COUTMAX/1000 -> 23.198065 | I37: =I35*COUTMAX/1000 -> 18.204913 | J37: =J35*COUTMAX/1000 -> 14.286487 | K37: =K35*COUTMAX/1000 -> 11.211463 | L37: =L35*COUTMAX/1000 -> 8.7983074 | ... X37: =X35*COUTMAX/1000 -> 0.48
D38: Total FET Energy (J) | E38: =$E$21+$E$22*E36/$E$23 -> 5 | F38: =$E$21+$E$22*F36/$E$23 -> 5 | G38: =$E$21+$E$22*G36/$E$23 -> 5 | H38: =$E$21+$E$22*H36/$E$23 -> 5 | I38: =$E$21+$E$22*I36/$E$23 -> 5 | J38: =$E$21+$E$22*J36/$E$23 -> 5 | K38: =$E$21+$E$22*K36/$E$23 -> 5 | L38: =$E$21+$E$22*L36/$E$23 -> 5 | ... X38: =$E$21+$E$22*X36/$E$23 -> 5
D39: Power (Vout= 0) , (W) | E39: =(E37+IF($E$26="Resistive",0,IF($E$25=0,$E$27,0)))*VINMAX -> 2400 | F39: =(F37+IF($E$26="Resistive",0,IF($E$25=0,$E$27,0)))*VINMAX -> 1883.4239 | G39: =(G37+IF($E$26="Resistive",0,IF($E$25=0,$E$27,0)))*VINMAX -> 1478.0357 | H39: =(H37+IF($E$26="Resistive",0,IF($E$25=0,$E$27,0)))*VINMAX -> 1159.9033 | I39: =(I37+IF($E$26="Resistive",0,IF($E$25=0,$E$27,0)))*VINMAX -> 910.24565 | J39: =(J37+IF($E$26="Resistive",0,IF($E$25=0,$E$27,0)))*VINMAX -> 714.32435 | K39: =(K37+IF($E$26="Resistive",0,IF($E$25=0,$E$27,0)))*VINMAX -> 560.57315 | L39: =(L37+IF($E$26="Resistive",0,IF($E$25=0,$E$27,0)))*VINMAX -> 439.91537 | ... X39: =(X37+IF($E$26="Resistive",0,IF($E$25=0,$E$27,0)))*VINMAX -> 24
D40: Power (load on), (W) | E40: =(E37+IF($E$26="Resistive", $E$25/$E$27,$E$27)) *(VINMAX-$E$25) -> 2400 | F40: =(F37+IF($E$26="Resistive", $E$25/$E$27,$E$27)) *(VINMAX-$E$25) -> 1883.4239 | G40: =(G37+IF($E$26="Resistive", $E$25/$E$27,$E$27)) *(VINMAX-$E$25) -> 1478.0357 | H40: =(H37+IF($E$26="Resistive", $E$25/$E$27,$E$27)) *(VINMAX-$E$25) -> 1159.9033 | I40: =(I37+IF($E$26="Resistive", $E$25/$E$27,$E$27)) *(VINMAX-$E$25) -> 910.24565 | J40: =(J37+IF($E$26="Resistive", $E$25/$E$27,$E$27)) *(VINMAX-$E$25) -> 714.32435 | K40: =(K37+IF($E$26="Resistive", $E$25/$E$27,$E$27)) *(VINMAX-$E$25) -> 560.57315 | L40: =(L37+IF($E$26="Resistive", $E$25/$E$27,$E$27)) *(VINMAX-$E$25) -> 439.91537 | ... X40: =(X37+IF($E$26="Resistive", $E$25/$E$27,$E$27)) *(VINMAX-$E$25) -> 24
D41: Vout (dP/dVout = 0) (V) | E41: =IF($E$26="Resistive", -$E$27*E37/2 + VINMAX/2, -1) -> -1 | F41: =IF($E$26="Resistive", -$E$27*F37/2 + VINMAX/2, -1) -> -1 | G41: =IF($E$26="Resistive", -$E$27*G37/2 + VINMAX/2, -1) -> -1 | H41: =IF($E$26="Resistive", -$E$27*H37/2 + VINMAX/2, -1) -> -1 | I41: =IF($E$26="Resistive", -$E$27*I37/2 + VINMAX/2, -1) -> -1 | J41: =IF($E$26="Resistive", -$E$27*J37/2 + VINMAX/2, -1) -> -1 | K41: =IF($E$26="Resistive", -$E$27*K37/2 + VINMAX/2, -1) -> -1 | L41: =IF($E$26="Resistive", -$E$27*L37/2 + VINMAX/2, -1) -> -1 | ... X41: =IF($E$26="Resistive", -$E$27*X37/2 + VINMAX/2, -1) -> -1
D42: Power (@ Vout above, if applicable) | E42: =IF(AND(E41<VINMAX, E41>$E$25), (VINMAX-E41)*(E37+E41/$E$27), 0) -> 0 | F42: =IF(AND(F41<VINMAX, F41>$E$25), (VINMAX-F41)*(F37+F41/$E$27), 0) -> 0 | G42: =IF(AND(G41<VINMAX, G41>$E$25), (VINMAX-G41)*(G37+G41/$E$27), 0) -> 0 | H42: =IF(AND(H41<VINMAX, H41>$E$25), (VINMAX-H41)*(H37+H41/$E$27), 0) -> 0 | I42: =IF(AND(I41<VINMAX, I41>$E$25), (VINMAX-I41)*(I37+I41/$E$27), 0) -> 0 | J42: =IF(AND(J41<VINMAX, J41>$E$25), (VINMAX-J41)*(J37+J41/$E$27), 0) -> 0 | K42: =IF(AND(K41<VINMAX, K41>$E$25), (VINMAX-K41)*(K37+K41/$E$27), 0) -> 0 | L42: =IF(AND(L41<VINMAX, L41>$E$25), (VINMAX-L41)*(L37+L41/$E$27), 0) -> 0 | ... X42: =IF(AND(X41<VINMAX, X41>$E$25), (VINMAX-X41)*(X37+X41/$E$27), 0) -> 0
D44: max power (W) | E44: =MAX(E39,E40,E42) -> 2400 | F44: =MAX(F39,F40,F42) -> 1883.4239 | G44: =MAX(G39,G40,G42) -> 1478.0357 | H44: =MAX(H39,H40,H42) -> 1159.9033 | I44: =MAX(I39,I40,I42) -> 910.24565 | J44: =MAX(J39,J40,J42) -> 714.32435 | K44: =MAX(K39,K40,K42) -> 560.57315 | L44: =MAX(L39,L40,L42) -> 439.91537 | ... X44: =MAX(X39,X40,X42) -> 24
D45: Equivalent time for SOA (ms) | E45: =E38/E44*1000 -> 2.0833333 | F45: =F38/F44*1000 -> 2.6547396 | G45: =G38/G44*1000 -> 3.3828682 | H45: =H38/H44*1000 -> 4.3107043 | I45: =I38/I44*1000 -> 5.4930227 | J45: =J38/J44*1000 -> 6.9996214 | K45: =K38/K44*1000 -> 8.9194425 | L45: =L38/L44*1000 -> 11.365822 | ... X45: =X38/X44*1000 -> 208.33333
D47: a | E47: =IF(E45<$J$23,$J$24,IF(E45<$K$23,$K$24,IF(E45<$L$23,$L$24,$M$24))) -> 81 | F47: =IF(F45<$J$23,$J$24,IF(F45<$K$23,$K$24,IF(F45<$L$23,$L$24,$M$24))) -> 81 | G47: =IF(G45<$J$23,$J$24,IF(G45<$K$23,$K$24,IF(G45<$L$23,$L$24,$M$24))) -> 81 | H47: =IF(H45<$J$23,$J$24,IF(H45<$K$23,$K$24,IF(H45<$L$23,$L$24,$M$24))) -> 81 | I47: =IF(I45<$J$23,$J$24,IF(I45<$K$23,$K$24,IF(I45<$L$23,$L$24,$M$24))) -> 81 | J47: =IF(J45<$J$23,$J$24,IF(J45<$K$23,$K$24,IF(J45<$L$23,$L$24,$M$24))) -> 81 | K47: =IF(K45<$J$23,$J$24,IF(K45<$K$23,$K$24,IF(K45<$L$23,$L$24,$M$24))) -> 81 | L47: =IF(L45<$J$23,$J$24,IF(L45<$K$23,$K$24,IF(L45<$L$23,$L$24,$M$24))) -> 51.428571 | ... X47: =IF(X45<$J$23,$J$24,IF(X45<$K$23,$K$24,IF(X45<$L$23,$L$24,$M$24))) -> 12.348
D48: m | E48: =IF(E45<$J$23,$J$25,IF(E45<$K$23,$K$25,IF(E45<$L$23,$L$25,$M$25))) -> -0.65321251 | F48: =IF(F45<$J$23,$J$25,IF(F45<$K$23,$K$25,IF(F45<$L$23,$L$25,$M$25))) -> -0.65321251 | G48: =IF(G45<$J$23,$J$25,IF(G45<$K$23,$K$25,IF(G45<$L$23,$L$25,$M$25))) -> -0.65321251 | H48: =IF(H45<$J$23,$J$25,IF(H45<$K$23,$K$25,IF(H45<$L$23,$L$25,$M$25))) -> -0.65321251 | I48: =IF(I45<$J$23,$J$25,IF(I45<$K$23,$K$25,IF(I45<$L$23,$L$25,$M$25))) -> -0.65321251 | J48: =IF(J45<$J$23,$J$25,IF(J45<$K$23,$K$25,IF(J45<$L$23,$L$25,$M$25))) -> -0.65321251 | K48: =IF(K45<$J$23,$J$25,IF(K45<$K$23,$K$25,IF(K45<$L$23,$L$25,$M$25))) -> -0.65321251 | L48: =IF(L45<$J$23,$J$25,IF(L45<$K$23,$K$25,IF(L45<$L$23,$L$25,$M$25))) -> -0.45593196 | ... X48: =IF(X45<$J$23,$J$25,IF(X45<$K$23,$K$25,IF(X45<$L$23,$L$25,$M$25))) -> -0.14612804
D50: Available SOA (W) | E50: =E47*E45^E48*VINMAX -> 2507.4819 | F50: =F47*F45^F48*VINMAX -> 2140.3195 | G50: =G47*G45^G48*VINMAX -> 1826.9194 | H50: =H47*H45^H48*VINMAX -> 1559.4095 | I50: =I47*I45^I48*VINMAX -> 1331.0702 | J50: =J47*J45^J48*VINMAX -> 1136.1659 | K50: =K47*K45^K48*VINMAX -> 969.8008 | L50: =L47*L45^L48*VINMAX -> 848.96991 | ... X50: =X47*X45^X48*VINMAX -> 282.96385
D51: Derated for Temp | E51: =E50*(TJMAX-$E$19)/(TJMAX - 25) -> 2153.4845 | F51: =F50*(TJMAX-$E$19)/(TJMAX - 25) -> 1838.1567 | G51: =G50*(TJMAX-$E$19)/(TJMAX - 25) -> 1569.0014 | H51: =H50*(TJMAX-$E$19)/(TJMAX - 25) -> 1339.2576 | I51: =I50*(TJMAX-$E$19)/(TJMAX - 25) -> 1143.1544 | J51: =J50*(TJMAX-$E$19)/(TJMAX - 25) -> 975.76601 | K51: =K50*(TJMAX-$E$19)/(TJMAX - 25) -> 832.88775 | L51: =L50*(TJMAX-$E$19)/(TJMAX - 25) -> 729.11533 | ... X51: =X50*(TJMAX-$E$19)/(TJMAX - 25) -> 243.01602
D52: SOA Margin | E52: =E51/E44 -> 0.8972852 | F52: =F51/F44 -> 0.97596546 | G52: =G51/G44 -> 1.061545 | H52: =H51/H44 -> 1.1546287 | I52: =I51/I44 -> 1.2558746 | J52: =J51/J44 -> 1.3659985 | K52: =K51/K44 -> 1.4857789 | L52: =L51/L44 -> 1.6573991 | ... X52: =X51/X44 -> 10.125667
...
